2022-08-21 20:13:29.500 WARNING (Recorder) [homeassistant.components.recorder.util] The system could not validate that the sqlite3 database at //config/home-assistant_v2.db was shutdown cleanly
2022-08-21 20:18:33.728 WARNING (SyncWorker_2) [pychromecast.controllers] Quick Play failed for https://www.home-assistant.io/images/cast/splash.png:image/png({})
2022-08-21 20:18:33.733 ERROR (MainThread) [homeassistant.core] Error executing service: <ServiceCall media_player.turn_on (c:01GB0PKAFETS70H3PP8QQC78YM): entity_id=['media_player.tlfzywn']>
Traceback (most recent call last):
  File "/usr/src/homeassistant/homeassistant/core.py", line 1731, in catch_exceptions
    await coro_or_task
  File "/usr/src/homeassistant/homeassistant/core.py", line 1750, in _execute_service
    await cast(Callable[[ServiceCall], Awaitable[None]], handler.job.target)(
  File "/usr/src/homeassistant/homeassistant/helpers/entity_component.py", line 204, in handle_service
    await service.entity_service_call(
  File "/usr/src/homeassistant/homeassistant/helpers/service.py", line 676, in entity_service_call
    future.result()  # pop exception if have
  File "/usr/src/homeassistant/homeassistant/helpers/entity.py", line 930, in async_request_call
    await coro
  File "/usr/src/homeassistant/homeassistant/helpers/service.py", line 713, in _handle_entity_call
    await result
  File "/usr/src/homeassistant/homeassistant/components/media_player/__init__.py", line 686, in async_turn_on
    await self.hass.async_add_executor_job(self.turn_on)
  File "/usr/local/lib/python3.10/concurrent/futures/thread.py", line 58, in run
    result = self.fn(*self.args, **self.kwargs)
  File "/usr/src/homeassistant/homeassistant/components/cast/media_player.py", line 508, in turn_on
    quick_play(self._chromecast, "default_media_receiver", app_data)
  File "/usr/local/lib/python3.10/site-packages/pychromecast/quick_play.py", line 77, in quick_play
    controller.quick_play(**data)
  File "/usr/local/lib/python3.10/site-packages/pychromecast/controllers/media.py", line 547, in quick_play
    raise PyChromecastError()
pychromecast.error.PyChromecastError
2022-08-21 20:32:29.725 ERROR (MainThread) [frontend.js.latest.202208020] :0:0 Script error.
2022-08-21 20:49:43.390 ERROR (MainThread) [aiohttp.server] Error handling request
Traceback (most recent call last):
  File "/usr/local/lib/python3.10/site-packages/aiohttp/web_protocol.py", line 334, in data_received
    messages, upgraded, tail = self._request_parser.feed_data(data)
  File "aiohttp/_http_parser.pyx", line 551, in aiohttp._http_parser.HttpParser.feed_data
aiohttp.http_exceptions.BadStatusLine: 400, message="Bad status line 'Invalid method encountered'"
2022-08-21 20:49:43.393 ERROR (MainThread) [aiohttp.server] Error handling request
Traceback (most recent call last):
  File "/usr/local/lib/python3.10/site-packages/aiohttp/web_protocol.py", line 334, in data_received
    messages, upgraded, tail = self._request_parser.feed_data(data)
  File "aiohttp/_http_parser.pyx", line 551, in aiohttp._http_parser.HttpParser.feed_data
aiohttp.http_exceptions.BadStatusLine: 400, message="Bad status line 'Invalid method encountered'"
2022-08-21 20:49:46.538 WARNING (MainThread) [homeassistant.components.http.ban] Login attempt or request with invalid authentication from 192.168.100.126 (192.168.100.126). Requested URL: '/auth/token'. (Mozilla/5.0 (Windows NT 10.0; Win64; x64) AppleWebKit/537.36 (KHTML, like Gecko) Chrome/104.0.0.0 Safari/537.36)
2022-08-21 20:49:46.614 WARNING (MainThread) [homeassistant.components.http.ban] Login attempt or request with invalid authentication from 192.168.100.126 (192.168.100.126). Requested URL: '/api/websocket'. (Mozilla/5.0 (Windows NT 10.0; Win64; x64) AppleWebKit/537.36 (KHTML, like Gecko) Chrome/104.0.0.0 Safari/537.36)
2022-08-21 23:23:22.005 ERROR (MainThread) [homeassistant.components.tplink.coordinator] Error fetching 192.168.100.145 data: Unable to connect to the device: 192.168.100.145: 
2022-08-21 23:23:23.007 ERROR (MainThread) [homeassistant.components.tplink.coordinator] Error fetching 192.168.100.146 data: Unable to connect to the device: 192.168.100.146: 
2022-08-21 23:24:36.969 WARNING (MainThread) [homeassistant.config_entries] Config entry 'مجفة وليد L KL130(EU)' for tplink integration not ready yet: Unable to connect to the device: 192.168.100.146: [Errno 113] Connect call failed ('192.168.100.146', 9999); Retrying in background
2022-08-21 23:24:43.291 WARNING (MainThread) [homeassistant.config_entries] Config entry 'نجفة غرفة وليدR KL130(EU)' for tplink integration not ready yet: Unable to connect to the device: 192.168.100.145: [Errno 113] Connect call failed ('192.168.100.145', 9999); Retrying in background
2022-08-21 23:25:04.058 WARNING (MainThread) [homeassistant.helpers.service] Unable to find referenced entities light.mjf_wlyd_l, light.njf_grf_wlydr or it is/they are currently not available
2022-08-21 23:46:12.154 ERROR (MainThread) [frontend.js.latest.202208020] :0:0 Script error.
2022-08-22 00:11:13.905 WARNING (SyncWorker_8) [pychromecast.controllers] PLAY command requested but no session is active.
2022-08-22 00:11:15.458 WARNING (SyncWorker_7) [pychromecast.controllers] PAUSE command requested but no session is active.
2022-08-22 00:11:16.572 WARNING (SyncWorker_3) [pychromecast.controllers] PLAY command requested but no session is active.
2022-08-22 00:11:17.286 WARNING (SyncWorker_1) [pychromecast.controllers] STOP command requested but no session is active.
2022-08-22 00:11:25.809 WARNING (SyncWorker_2) [pychromecast.controllers] PLAY command requested but no session is active.
2022-08-22 00:11:27.123 WARNING (SyncWorker_7) [pychromecast.controllers] PLAY command requested but no session is active.
2022-08-22 13:02:54.441 WARNING (MainThread) [homeassistant.components.http.ban] Login attempt or request with invalid authentication from localhost (127.0.0.1). Requested URL: '/auth/login_flow/9c3bb3b19b1f55f3a51a83ee406330d9'. (Mozilla/5.0 (Macintosh; Intel Mac OS X 10_15_7) AppleWebKit/537.36 (KHTML, like Gecko) Chrome/104.0.0.0 Safari/537.36)
2022-08-22 13:07:49.212 WARNING (MainThread) [homeassistant.components.http.ban] Login attempt or request with invalid authentication from localhost (127.0.0.1). Requested URL: '/auth/login_flow/9c3bb3b19b1f55f3a51a83ee406330d9'. (Mozilla/5.0 (Macintosh; Intel Mac OS X 10_15_7) AppleWebKit/537.36 (KHTML, like Gecko) Chrome/104.0.0.0 Safari/537.36)
2022-08-22 13:08:23.860 WARNING (MainThread) [homeassistant.components.http.ban] Login attempt or request with invalid authentication from localhost (127.0.0.1). Requested URL: '/auth/login_flow/bb8bee0d1768b63efd536bf622557974'. (Mozilla/5.0 (Macintosh; Intel Mac OS X 10_15_7) AppleWebKit/537.36 (KHTML, like Gecko) Chrome/104.0.0.0 Safari/537.36)
2022-08-22 13:13:46.236 WARNING (MainThread) [homeassistant.helpers.state] Integration sensor does not support reproduce state
